<?xml version="1.0" encoding="utf-8"?>
<!-- This URDF was automatically created by SolidWorks to URDF Exporter! Originally created by Stephen Brawner (brawner@gmail.com) 
     Commit Version: 1.6.0-4-g7f85cfe  Build Version: 1.6.7995.38578
     For more information, please see http://wiki.ros.org/sw_urdf_exporter -->
<robot
  name="QUB v1.2_urdf_4th">
  <link
    name="base_link">
    <inertial>
      <origin
        xyz="9.972868932695E-05 -0.00184230728434962 0.00404226051952403"
        rpy="0 0 0" />
      <mass
        value="4.07254209371122" />
      <inertia
        ixx="0.0110944195902349"
        ixy="-9.87243046524986E-06"
        ixz="-3.3876875264419E-06"
        iyy="0.00673983708794245"
        iyz="5.97941069937372E-05"
        izz="0.00999680434458651" />
    </inertial>
    <visual>
      <origin
        xyz="0 0 0"
        rpy="0 0 0" />
      <geometry>
        <mesh
          filename="file:///Users/jae/Library/Mobile Documents/com~apple~CloudDocs/KUDOS/Humanoid/8. URDF 작업/URDF_study/src/QUB_urdf/meshes/base_link.STL" />
      </geometry>
      <material
        name="">
        <color
          rgba="0.752941176470588 0.752941176470588 0.752941176470588 1" />
      </material>
    </visual>
    <collision>
      <origin
        xyz="0 0 0"
        rpy="0 0 0" />
      <geometry>
        <mesh
          filename="file:///Users/jae/Library/Mobile Documents/com~apple~CloudDocs/KUDOS/Humanoid/8. URDF 작업/URDF_study/src/QUB_urdf/meshes/base_link.STL" />
      </geometry>
    </collision>
  </link>
  <link
    name="pelvis_link">
    <inertial>
      <origin
        xyz="-0.00065316817187866 0.00020290159996305 0.0358808578163774"
        rpy="0 0 0" />
      <mass
        value="2.18597276276807" />
      <inertia
        ixx="0.00340799392796046"
        ixy="-5.2740435801549E-07"
        ixz="3.53216953286813E-05"
        iyy="0.00424616615014973"
        iyz="8.46691439586804E-07"
        izz="0.00475970108323435" />
    </inertial>
    <visual>
      <origin
        xyz="0 0 0"
        rpy="0 0 0" />
      <geometry>
        <mesh
          filename="file:///Users/jae/Library/Mobile Documents/com~apple~CloudDocs/KUDOS/Humanoid/8. URDF 작업/URDF_study/src/QUB_urdf/meshes/pelvis_link.STL" />
      </geometry>
      <material
        name="">
        <color
          rgba="0.752941176470588 0.752941176470588 0.752941176470588 1" />
      </material>
    </visual>
    <collision>
      <origin
        xyz="0 0 0"
        rpy="0 0 0" />
      <geometry>
        <mesh
          filename="file:///Users/jae/Library/Mobile Documents/com~apple~CloudDocs/KUDOS/Humanoid/8. URDF 작업/URDF_study/src/QUB_urdf/meshes/pelvis_link.STL" />
      </geometry>
    </collision>
  </link>
  <joint
    name="torso_yaw_joint"
    type="revolute">
    <origin
      xyz="0 0 -0.241618109476686"
      rpy="0 0 0" />
    <parent
      link="base_link" />
    <child
      link="pelvis_link" />
    <axis
      xyz="0 0 1" />
    <limit
      lower="-0.7854" upper="0.7854" effort="60" velocity="5.0" />
  </joint>
  <link
    name="R_hip_r_link">
    <inertial>
      <origin
        xyz="0.00116757568393022 0.00446075365470017 -0.000680608741054189"
        rpy="0 0 0" />
      <mass
        value="0.855799021923541" />
      <inertia
        ixx="0.00142232323448987"
        ixy="7.59430559489954E-06"
        ixz="2.70988420937276E-06"
        iyy="0.000903912729790728"
        iyz="-9.49906807823523E-06"
        izz="0.000834999214630275" />
    </inertial>
    <visual>
      <origin
        xyz="0 0 0"
        rpy="0 0 0" />
      <geometry>
        <mesh
          filename="file:///Users/jae/Library/Mobile Documents/com~apple~CloudDocs/KUDOS/Humanoid/8. URDF 작업/URDF_study/src/QUB_urdf/meshes/R_hip_r_link.STL" />
      </geometry>
      <material
        name="">
        <color
          rgba="0.752941176470588 0.752941176470588 0.752941176470588 1" />
      </material>
    </visual>
    <collision>
      <origin
        xyz="0 0 0"
        rpy="0 0 0" />
      <geometry>
        <mesh
          filename="file:///Users/jae/Library/Mobile Documents/com~apple~CloudDocs/KUDOS/Humanoid/8. URDF 작업/URDF_study/src/QUB_urdf/meshes/R_hip_r_link.STL" />
      </geometry>
    </collision>
  </link>
  <joint
    name="R_hip_pitch_joint"
    type="revolute">
    <origin
      xyz="0 -0.115900000000167 0"
      rpy="0 0 0" />
    <parent
      link="pelvis_link" />
    <child
      link="R_hip_r_link" />
    <axis
      xyz="0 1 0" />
    <limit
      lower="-1.5708" upper="0.5236" effort="60" velocity="5.0" />
  </joint>
  <link
    name="R_hip_y_link">
    <inertial>
      <origin
        xyz="-0.00193262979343767 -0.000372969854493893 -0.0843684105242438"
        rpy="0 0 0" />
      <mass
        value="0.9177638118792" />
      <inertia
        ixx="0.00127188935301418"
        ixy="-1.30004100565645E-05"
        ixz="5.14550324155258E-05"
        iyy="0.00152670536508679"
        iyz="1.71066628651132E-05"
        izz="0.0015116363451662" />
    </inertial>
    <visual>
      <origin
        xyz="0 0 0"
        rpy="0 0 0" />
      <geometry>
        <mesh
          filename="file:///Users/jae/Library/Mobile Documents/com~apple~CloudDocs/KUDOS/Humanoid/8. URDF 작업/URDF_study/src/QUB_urdf/meshes/R_hip_y_link.STL" />
      </geometry>
      <material
        name="">
        <color
          rgba="0.752941176470588 0.752941176470588 0.752941176470588 1" />
      </material>
    </visual>
    <collision>
      <origin
        xyz="0 0 0"
        rpy="0 0 0" />
      <geometry>
        <mesh
          filename="file:///Users/jae/Library/Mobile Documents/com~apple~CloudDocs/KUDOS/Humanoid/8. URDF 작업/URDF_study/src/QUB_urdf/meshes/R_hip_y_link.STL" />
      </geometry>
    </collision>
  </link>
  <joint
    name="R_hip_roll_joint"
    type="revolute">
    <origin
      xyz="0 0 0"
      rpy="0 0 0" />
    <parent
      link="R_hip_r_link" />
    <child
      link="R_hip_y_link" />
    <axis
      xyz="1 0 0" />
    <limit
      lower="-2.4" upper="0" effort="60" velocity="5.0" />
  </joint>
  <link
    name="R_thigh_link">
    <inertial>
      <origin
        xyz="-0.00435238054703091 -0.00416319589959019 -0.00394213537966093"
        rpy="0 0 0" />
      <mass
        value="1.3747257194995" />
      <inertia
        ixx="0.00370513003093616"
        ixy="3.44046974970439E-05"
        ixz="-0.000169546059805682"
        iyy="0.00392291926166622"
        iyz="-9.69048886339927E-05"
        izz="0.00231136339061033" />
    </inertial>
    <visual>
      <origin
        xyz="0 0 0"
        rpy="0 0 0" />
      <geometry>
        <mesh
          filename="file:///Users/jae/Library/Mobile Documents/com~apple~CloudDocs/KUDOS/Humanoid/8. URDF 작업/URDF_study/src/QUB_urdf/meshes/R_thigh_link.STL" />
      </geometry>
      <material
        name="">
        <color
          rgba="0.752941176470588 0.752941176470588 0.752941176470588 1" />
      </material>
    </visual>
    <collision>
      <origin
        xyz="0 0 0"
        rpy="0 0 0" />
      <geometry>
        <mesh
          filename="file:///Users/jae/Library/Mobile Documents/com~apple~CloudDocs/KUDOS/Humanoid/8. URDF 작업/URDF_study/src/QUB_urdf/meshes/R_thigh_link.STL" />
      </geometry>
    </collision>
  </link>
  <joint
    name="R_hip_yaw_joint"
    type="revolute">
    <origin
      xyz="0 0 -0.211750000000001"
      rpy="0 0 0" />
    <parent
      link="R_hip_y_link" />
    <child
      link="R_thigh_link" />
    <axis
      xyz="0 0 1" />
    <limit
      lower="-0.5236" upper="0.5236" effort="60" velocity="5.0" />
  </joint>
  <link
    name="R_calf_link">
    <inertial>
      <origin
        xyz="0.0257855571086101 0.00175538373979603 -0.0849093460397078"
        rpy="0 0 0" />
      <mass
        value="1.17074722849011" />
      <inertia
        ixx="0.00171475366464367"
        ixy="1.21634495123499E-05"
        ixz="1.29104743950714E-05"
        iyy="0.00205284117260452"
        iyz="-3.91070963302854E-05"
        izz="0.000822263616014289" />
    </inertial>
    <visual>
      <origin
        xyz="0 0 0"
        rpy="0 0 0" />
      <geometry>
        <mesh
          filename="file:///Users/jae/Library/Mobile Documents/com~apple~CloudDocs/KUDOS/Humanoid/8. URDF 작업/URDF_study/src/QUB_urdf/meshes/R_calf_link.STL" />
      </geometry>
      <material
        name="">
        <color
          rgba="0.752941176470588 0.752941176470588 0.752941176470588 1" />
      </material>
    </visual>
    <collision>
      <origin
        xyz="0 0 0"
        rpy="0 0 0" />
      <geometry>
        <mesh
          filename="file:///Users/jae/Library/Mobile Documents/com~apple~CloudDocs/KUDOS/Humanoid/8. URDF 작업/URDF_study/src/QUB_urdf/meshes/R_calf_link.STL" />
      </geometry>
    </collision>
  </link>
  <joint
    name="R_knee_pitch_joint"
    type="revolute">
    <origin
      xyz="-0.0297924314284872 -0.000149999999114303 -0.0900000000000005"
      rpy="0 0 0" />
    <parent
      link="R_thigh_link" />
    <child
      link="R_calf_link" />
    <axis
      xyz="0 -1 0" />
    <limit
      lower="-1.9" upper="0.0" effort="120" velocity="5.0" />
  </joint>
  <link
    name="R_ankle_link">
    <inertial>
      <origin
        xyz="9.93627402579023E-12 4.34652314140749E-14 -7.07699949722418E-05"
        rpy="0 0 0" />
      <mass
        value="0.0236524344915325" />
      <inertia
        ixx="2.14621271212167E-06"
        ixy="-1.95834100604865E-18"
        ixz="-5.52641697689679E-21"
        iyy="5.25984318580439E-06"
        iyz="-1.75085879152675E-19"
        izz="5.68025550439875E-06" />
    </inertial>
    <visual>
      <origin
        xyz="0 0 0"
        rpy="0 0 0" />
      <geometry>
        <mesh
          filename="file:///Users/jae/Library/Mobile Documents/com~apple~CloudDocs/KUDOS/Humanoid/8. URDF 작업/URDF_study/src/QUB_urdf/meshes/R_ankle_link.STL" />
      </geometry>
      <material
        name="">
        <color
          rgba="0.698039215686274 0.698039215686274 0.698039215686274 1" />
      </material>
    </visual>
    <collision>
      <origin
        xyz="0 0 0"
        rpy="0 0 0" />
      <geometry>
        <mesh
          filename="file:///Users/jae/Library/Mobile Documents/com~apple~CloudDocs/KUDOS/Humanoid/8. URDF 작업/URDF_study/src/QUB_urdf/meshes/R_ankle_link.STL" />
      </geometry>
    </collision>
  </link>
  <joint
    name="R_ankle_pitch_joint"
    type="revolute">
    <origin
      xyz="0.0299999999901397 0.000150000000093992 -0.26800000000117"
      rpy="0 0 0" />
    <parent
      link="R_calf_link" />
    <child
      link="R_ankle_link" />
    <axis
      xyz="0 -1 0" />
    <limit
      lower="-0.5236" upper="0.7854" effort="17" velocity="5.0" />
  </joint>
  <link
    name="R_foot_link">
    <inertial>
      <origin
        xyz="0.00281002117315343 1.15196546746077E-09 -0.0247444315754096"
        rpy="0 0 0" />
      <mass
        value="0.359946538045687" />
      <inertia
        ixx="0.000172850016569842"
        ixy="7.47418435363811E-11"
        ixz="4.71246918661337E-06"
        iyy="0.000707347379152277"
        iyz="-8.79360793372591E-12"
        izz="0.000833012357986271" />
    </inertial>
    <visual>
      <origin
        xyz="0 0 0"
        rpy="0 0 0" />
      <geometry>
        <mesh
          filename="file:///Users/jae/Library/Mobile Documents/com~apple~CloudDocs/KUDOS/Humanoid/8. URDF 작업/URDF_study/src/QUB_urdf/meshes/R_foot_link.STL" />
      </geometry>
      <material
        name="">
        <color
          rgba="0.752941176470588 0.752941176470588 0.752941176470588 1" />
      </material>
    </visual>
    <collision>
      <origin
        xyz="0 0 0"
        rpy="0 0 0" />
      <geometry>
        <mesh
          filename="file:///Users/jae/Library/Mobile Documents/com~apple~CloudDocs/KUDOS/Humanoid/8. URDF 작업/URDF_study/src/QUB_urdf/meshes/R_foot_link.STL" />
      </geometry>
    </collision>
  </link>
  <joint
    name="R_ankle_roll_joint"
    type="revolute">
    <origin
      xyz="0 0 0"
      rpy="0 0 0" />
    <parent
      link="R_ankle_link" />
    <child
      link="R_foot_link" />
    <axis
      xyz="1 0 0" />
    <limit
      lower="-0.3491" upper="0.3491" effort="17" velocity="5.0" />
  </joint>
  <link
    name="L_hip_r_link">
    <inertial>
      <origin
        xyz="0.00116757776912291 -0.00442532542451377 -0.000656233448862675"
        rpy="0 0 0" />
      <mass
        value="0.855798957044734" />
      <inertia
        ixx="0.00142232310214843"
        ixy="-7.88546923555298E-06"
        ixz="2.80910297330463E-06"
        iyy="0.000903912674175719"
        iyz="8.4645114712968E-06"
        izz="0.000834999136601076" />
    </inertial>
    <visual>
      <origin
        xyz="0 0 0"
        rpy="0 0 0" />
      <geometry>
        <mesh
          filename="file:///Users/jae/Library/Mobile Documents/com~apple~CloudDocs/KUDOS/Humanoid/8. URDF 작업/URDF_study/src/QUB_urdf/meshes/L_hip_r_link.STL" />
      </geometry>
      <material
        name="">
        <color
          rgba="0.752941176470588 0.752941176470588 0.752941176470588 1" />
      </material>
    </visual>
    <collision>
      <origin
        xyz="0 0 0"
        rpy="0 0 0" />
      <geometry>
        <mesh
          filename="file:///Users/jae/Library/Mobile Documents/com~apple~CloudDocs/KUDOS/Humanoid/8. URDF 작업/URDF_study/src/QUB_urdf/meshes/L_hip_r_link.STL" />
      </geometry>
    </collision>
  </link>
  <joint
    name="L_hip_pitch_joint"
    type="revolute">
    <origin
      xyz="0 0.116500000000629 0"
      rpy="0 0 0" />
    <parent
      link="pelvis_link" />
    <child
      link="L_hip_r_link" />
    <axis
      xyz="0 1 0" />
    <limit
      lower="-1.5708" upper="0.5236" effort="60" velocity="5.0" />
  </joint>
  <link
    name="L_hip_y_link">
    <inertial>
      <origin
        xyz="-0.00193252971270041 0.000177003248463772 -0.084368588275626"
        rpy="0 0 0" />
      <mass
        value="0.917755275631564" />
      <inertia
        ixx="0.00127188479957326"
        ixy="6.56806506297276E-06"
        ixz="5.14561266537536E-05"
        iyy="0.00152669828170975"
        iyz="-1.62300953527453E-05"
        izz="0.00151162872907598" />
    </inertial>
    <visual>
      <origin
        xyz="0 0 0"
        rpy="0 0 0" />
      <geometry>
        <mesh
          filename="file:///Users/jae/Library/Mobile Documents/com~apple~CloudDocs/KUDOS/Humanoid/8. URDF 작업/URDF_study/src/QUB_urdf/meshes/L_hip_y_link.STL" />
      </geometry>
      <material
        name="">
        <color
          rgba="0.752941176470588 0.752941176470588 0.752941176470588 1" />
      </material>
    </visual>
    <collision>
      <origin
        xyz="0 0 0"
        rpy="0 0 0" />
      <geometry>
        <mesh
          filename="file:///Users/jae/Library/Mobile Documents/com~apple~CloudDocs/KUDOS/Humanoid/8. URDF 작업/URDF_study/src/QUB_urdf/meshes/L_hip_y_link.STL" />
      </geometry>
    </collision>
  </link>
  <joint
    name="L_hip_roll_joint"
    type="revolute">
    <origin
      xyz="0 0 0"
      rpy="0 0 0" />
    <parent
      link="L_hip_r_link" />
    <child
      link="L_hip_y_link" />
    <axis
      xyz="1 0 0" />
    <limit
      lower="0" upper="2.4" effort="60" velocity="5.0" />
  </joint>
  <link
    name="L_thigh_link">
    <inertial>
      <origin
        xyz="-0.00431294610799449 0.00416323658644012 -0.00444992399149846"
        rpy="0 0 0" />
      <mass
        value="1.37472432263504" />
      <inertia
        ixx="0.00369686938981796"
        ixy="-3.43708636131834E-05"
        ixz="-0.000173512741734514"
        iyy="0.00392301712502097"
        iyz="9.66077955433136E-05"
        izz="0.00231972620326984" />
    </inertial>
    <visual>
      <origin
        xyz="0 0 0"
        rpy="0 0 0" />
      <geometry>
        <mesh
          filename="file:///Users/jae/Library/Mobile Documents/com~apple~CloudDocs/KUDOS/Humanoid/8. URDF 작업/URDF_study/src/QUB_urdf/meshes/L_thigh_link.STL" />
      </geometry>
      <material
        name="">
        <color
          rgba="0.752941176470588 0.752941176470588 0.752941176470588 1" />
      </material>
    </visual>
    <collision>
      <origin
        xyz="0 0 0"
        rpy="0 0 0" />
      <geometry>
        <mesh
          filename="file:///Users/jae/Library/Mobile Documents/com~apple~CloudDocs/KUDOS/Humanoid/8. URDF 작업/URDF_study/src/QUB_urdf/meshes/L_thigh_link.STL" />
      </geometry>
    </collision>
  </link>
  <joint
    name="L_hip_yaw_joint"
    type="revolute">
    <origin
      xyz="0 0 -0.211750000000039"
      rpy="0 0 0" />
    <parent
      link="L_hip_y_link" />
    <child
      link="L_thigh_link" />
    <axis
      xyz="0 0 1" />
    <limit
      lower="-0.5236" upper="0.5236" effort="60" velocity="5.0" />
  </joint>
  <link
    name="L_calf_link">
    <inertial>
      <origin
        xyz="0.0257936585773364 -0.00158074830359972 -0.0852552504994251"
        rpy="0 0 0" />
      <mass
        value="1.17074765561419" />
      <inertia
        ixx="0.00171485594395473"
        ixy="-1.21493967413841E-05"
        ixz="1.07228285898189E-05"
        iyy="0.00205284078481852"
        iyz="3.91222389076339E-05"
        izz="0.000822161522384275" />
    </inertial>
    <visual>
      <origin
        xyz="0 0 0"
        rpy="0 0 0" />
      <geometry>
        <mesh
          filename="file:///Users/jae/Library/Mobile Documents/com~apple~CloudDocs/KUDOS/Humanoid/8. URDF 작업/URDF_study/src/QUB_urdf/meshes/L_calf_link.STL" />
      </geometry>
      <material
        name="">
        <color
          rgba="0.752941176470588 0.752941176470588 0.752941176470588 1" />
      </material>
    </visual>
    <collision>
      <origin
        xyz="0 0 0"
        rpy="0 0 0" />
      <geometry>
        <mesh
          filename="file:///Users/jae/Library/Mobile Documents/com~apple~CloudDocs/KUDOS/Humanoid/8. URDF 작업/URDF_study/src/QUB_urdf/meshes/L_calf_link.STL" />
      </geometry>
    </collision>
  </link>
  <joint
    name="L_knee_pitch_joint"
    type="revolute">
    <origin
      xyz="-0.0297924314283908 -0.00015000000003787 -0.0900000000000123"
      rpy="0 0 0" />
    <parent
      link="L_thigh_link" />
    <child
      link="L_calf_link" />
    <axis
      xyz="0 -1 0" />
    <limit
      lower="-1.9" upper="0.0" effort="120" velocity="5.0" />
  </joint>
  <link
    name="L_ankle_link">
    <inertial>
      <origin
        xyz="1.88737914186277E-14 -1.81660242404291E-14 -7.07699971448372E-05"
        rpy="0 0 0" />
      <mass
        value="0.0236524344915325" />
      <inertia
        ixx="2.14621271212167E-06"
        ixy="-1.95588918010656E-18"
        ixz="-5.28026682501599E-20"
        iyy="5.25984318580435E-06"
        iyz="-1.77058166500656E-19"
        izz="5.68025550439871E-06" />
    </inertial>
    <visual>
      <origin
        xyz="0 0 0"
        rpy="0 0 0" />
      <geometry>
        <mesh
          filename="file:///Users/jae/Library/Mobile Documents/com~apple~CloudDocs/KUDOS/Humanoid/8. URDF 작업/URDF_study/src/QUB_urdf/meshes/L_ankle_link.STL" />
      </geometry>
      <material
        name="">
        <color
          rgba="0.698039215686274 0.698039215686274 0.698039215686274 1" />
      </material>
    </visual>
    <collision>
      <origin
        xyz="0 0 0"
        rpy="0 0 0" />
      <geometry>
        <mesh
          filename="file:///Users/jae/Library/Mobile Documents/com~apple~CloudDocs/KUDOS/Humanoid/8. URDF 작업/URDF_study/src/QUB_urdf/meshes/L_ankle_link.STL" />
      </geometry>
    </collision>
  </link>
  <joint
    name="L_ankle_pitch_joint"
    type="revolute">
    <origin
      xyz="0.0300000000000302 0.000150000000055842 -0.267999999998874"
      rpy="0 0 0" />
    <parent
      link="L_calf_link" />
    <child
      link="L_ankle_link" />
    <axis
      xyz="0 1 0" />
    <limit
      lower="-0.5236" upper="0.7854" effort="17" velocity="5.0" />
  </joint>
  <link
    name="L_foot_link">
    <inertial>
      <origin
        xyz="0.00281002105799422 1.14222183100754E-09 -0.0247444316160004"
        rpy="0 0 0" />
      <mass
        value="0.359946537295079" />
      <inertia
        ixx="0.000172850016458837"
        ixy="7.47277270667904E-11"
        ixz="4.71246914305163E-06"
        iyy="0.0007073473790065"
        iyz="-8.75119830847198E-12"
        izz="0.000833012357958703" />
    </inertial>
    <visual>
      <origin
        xyz="0 0 0"
        rpy="0 0 0" />
      <geometry>
        <mesh
          filename="file:///Users/jae/Library/Mobile Documents/com~apple~CloudDocs/KUDOS/Humanoid/8. URDF 작업/URDF_study/src/QUB_urdf/meshes/L_foot_link.STL" />
      </geometry>
      <material
        name="">
        <color
          rgba="0.752941176470588 0.752941176470588 0.752941176470588 1" />
      </material>
    </visual>
    <collision>
      <origin
        xyz="0 0 0"
        rpy="0 0 0" />
      <geometry>
        <mesh
          filename="file:///Users/jae/Library/Mobile Documents/com~apple~CloudDocs/KUDOS/Humanoid/8. URDF 작업/URDF_study/src/QUB_urdf/meshes/L_foot_link.STL" />
      </geometry>
    </collision>
  </link>
  <joint
    name="L_ankle_roll_joint"
    type="revolute">
    <origin
      xyz="0 0 0"
      rpy="0 0 0" />
    <parent
      link="L_ankle_link" />
    <child
      link="L_foot_link" />
    <axis
      xyz="1 0 0" />
    <limit
      lower="-0.3491" upper="0.3491" effort="17" velocity="5.0" />
  </joint>
</robot>