<?xml version="1.0" encoding="utf-8"?>
<!-- This URDF was automatically created by SolidWorks to URDF Exporter! Originally created by Stephen Brawner (brawner@gmail.com) 
     Commit Version: 1.6.0-4-g7f85cfe  Build Version: 1.6.7995.38578
     For more information, please see http://wiki.ros.org/sw_urdf_exporter -->
<robot
  name="QUB v1.2 urdf">
  <link
    name="base_link">
    <inertial>
      <origin
        xyz="0.0001 -0.00145 -0.00018"
        rpy="0 0 0" />
      <mass
        value="4.21449" />
      <inertia
        ixx="0.048051"
        ixy="0.000022089"
        ixz="-0.000049922"
        iyy="0.041201"
        iyz="0.0014077"
        izz="0.021693" />
    </inertial>
    <visual>
      <origin
        xyz="0 0 0"
        rpy="0 0 0" />
      <geometry>
        <mesh
          filename="file:///Users/jae/Library/Mobile Documents/com~apple~CloudDocs/KUDOS/Humanoid/8. URDF 작업/URDF_study/src/QUB_URDF_fin/meshes/base_link.STL" />
      </geometry>
      <material
        name="">
        <color
          rgba="0.75294 0.75294 0.75294 1" />
      </material>
    </visual>
    <collision>
      <origin
        xyz="0 0 0"
        rpy="0 0 0" />
      <geometry>
        <mesh
          filename="file:///Users/jae/Library/Mobile Documents/com~apple~CloudDocs/KUDOS/Humanoid/8. URDF 작업/URDF_study/src/QUB_URDF_fin/meshes/base_link.STL" />
      </geometry>
    </collision>
  </link>
  <link
    name="pelvis_link">
    <inertial>
      <origin
        xyz="-0.00036 0.00024 0.03233"
        rpy="0 0 0" />
      <mass
        value="3.69660" />
      <inertia
        ixx="0.012187"
        ixy="-0.000011794"
        ixz="-0.000096093"
        iyy="0.011785"
        iyz="0.0000034329"
        izz="0.0075662" />
    </inertial>
    <visual>
      <origin
        xyz="0 0 0"
        rpy="0 0 0" />
      <geometry>
        <mesh
          filename="file:///Users/jae/Library/Mobile Documents/com~apple~CloudDocs/KUDOS/Humanoid/8. URDF 작업/URDF_study/src/QUB_URDF_fin/meshes/pelvis_link.STL" />
      </geometry>
      <material
        name="">
        <color
          rgba="0.752941176470588 0.752941176470588 0.752941176470588 1" />
      </material>
    </visual>
    <collision>
      <origin
        xyz="0 0 0"
        rpy="0 0 0" />
      <geometry>
        <mesh
          filename="file:///Users/jae/Library/Mobile Documents/com~apple~CloudDocs/KUDOS/Humanoid/8. URDF 작업/URDF_study/src/QUB_URDF_fin/meshes/pelvis_link.STL" />
      </geometry>
    </collision>
  </link>
  <joint
    name="torso_yaw_joint"
    type="revolute">
    <origin
      xyz="0 0 -0.24162"
      rpy="0 0 0" />
    <parent
      link="base_link" />
    <child
      link="pelvis_link" />
    <axis
      xyz="0 0 1" />
    <limit
      lower="-1.57"
      upper="1.57"
      effort="100"
      velocity="10" />
  </joint>
  <link
    name="R_hip_r_link">
    <inertial>
      <origin
        xyz="0.00347 0.00277 -0.00048"
        rpy="0 0 0" />
      <mass
        value="1.24854" />
      <inertia
        ixx="0.0018401"
        ixy="-0.00000032265"
        ixz="0.0000071076"
        iyy="0.0013999"
        iyz="0.000010876"
        izz="0.0013711" />
    </inertial>
    <visual>
      <origin
        xyz="0 0 0"
        rpy="0 0 0" />
      <geometry>
        <mesh
          filename="file:///Users/jae/Library/Mobile Documents/com~apple~CloudDocs/KUDOS/Humanoid/8. URDF 작업/URDF_study/src/QUB_URDF_fin/meshes/R_hip_r_link.STL" />
      </geometry>
      <material
        name="">
        <color
          rgba="0.75294 0.75294 0.75294 1" />
      </material>
    </visual>
    <collision>
      <origin
        xyz="0 0 0"
        rpy="0 0 0" />
      <geometry>
        <mesh
          filename="file:///Users/jae/Library/Mobile Documents/com~apple~CloudDocs/KUDOS/Humanoid/8. URDF 작업/URDF_study/src/QUB_URDF_fin/meshes/R_hip_r_link.STL" />
      </geometry>
    </collision>
  </link>
  <joint
    name="R_hip_pitch_joint"
    type="revolute">
    <origin
      xyz="0 -0.1159 0"
      rpy="0 0 0" />
    <parent
      link="pelvis_link" />
    <child
      link="R_hip_r_link" />
    <axis
      xyz="0 1 0" />
    <limit
      lower="-1.57"
      upper="1.57"
      effort="150"
      velocity="10" />
  </joint>
  <link
    name="R_hip_y_link">
    <inertial>
      <origin
        xyz="-0.00135 -0.00025 -0.09201"
        rpy="0 0 0" />
      <mass
        value="1.32879" />
      <inertia
        ixx="0.0024344"
        ixy="0.000013039"
        ixz="-0.00013352"
        iyy="0.0027093"
        iyz="-0.000022509"
        izz="0.0019780" />
    </inertial>
    <visual>
      <origin
        xyz="0 0 0"
        rpy="0 0 0" />
      <geometry>
        <mesh
          filename="file:///Users/jae/Library/Mobile Documents/com~apple~CloudDocs/KUDOS/Humanoid/8. URDF 작업/URDF_study/src/QUB_URDF_fin/meshes/R_hip_y_link.STL" />
      </geometry>
      <material
        name="">
        <color
          rgba="0.75294 0.75294 0.75294 1" />
      </material>
    </visual>
    <collision>
      <origin
        xyz="0 0 0"
        rpy="0 0 0" />
      <geometry>
        <mesh
          filename="file:///Users/jae/Library/Mobile Documents/com~apple~CloudDocs/KUDOS/Humanoid/8. URDF 작업/URDF_study/src/QUB_URDF_fin/meshes/R_hip_y_link.STL" />
      </geometry>
    </collision>
  </link>
  <joint
    name="R_hip_roll_joint"
    type="revolute">
    <origin
      xyz="0 0 0"
      rpy="0 0 0" />
    <parent
      link="R_hip_r_link" />
    <child
      link="R_hip_y_link" />
    <axis
      xyz="1 0 0" />
    <limit
      lower="-0.78"
      upper="0.78"
      effort="150"
      velocity="10" />
  </joint>
  <link
    name="R_thigh_link">
    <inertial>
      <origin
        xyz="-0.00659 -0.01600 -0.00218"
        rpy="0 0 0" />
      <mass
        value="2.18164" />
      <inertia
        ixx="0.0052252"
        ixy="0.00017617"
        ixz="0.000090039"
        iyy="0.0051854"
        iyz="-0.000055426"
        izz="0.0040697" />
    </inertial>
    <visual>
      <origin
        xyz="0 0 0"
        rpy="0 0 0" />
      <geometry>
        <mesh
          filename="file:///Users/jae/Library/Mobile Documents/com~apple~CloudDocs/KUDOS/Humanoid/8. URDF 작업/URDF_study/src/QUB_URDF_fin/meshes/R_thigh_link.STL" />
      </geometry>
      <material
        name="">
        <color
          rgba="0.75294 0.75294 0.75294 1" />
      </material>
    </visual>
    <collision>
      <origin
        xyz="0 0 0"
        rpy="0 0 0" />
      <geometry>
        <mesh
          filename="file:///Users/jae/Library/Mobile Documents/com~apple~CloudDocs/KUDOS/Humanoid/8. URDF 작업/URDF_study/src/QUB_URDF_fin/meshes/R_thigh_link.STL" />
      </geometry>
    </collision>
  </link>
  <joint
    name="R_hip_yaw_joint"
    type="revolute">
    <origin
      xyz="0 0 -0.21175"
      rpy="0 0 0" />
    <parent
      link="R_hip_y_link" />
    <child
      link="R_thigh_link" />
    <axis
      xyz="0 0 1" />
    <limit
      lower="-0.78"
      upper="0.78"
      effort="100"
      velocity="10" />
  </joint>
  <link
    name="R_calf_link">
    <inertial>
      <origin
        xyz="0.01269 0.00090 -0.10244"
        rpy="0 0 0" />
      <mass
        value="1.97157" />
      <inertia
        ixx="0.011151"
        ixy="0.000015627"
        ixz="0.0019738"
        iyy="0.011825"
        iyz="0.00018350"
        izz="0.0038490" />
    </inertial>
    <visual>
      <origin
        xyz="0 0 0"
        rpy="0 0 0" />
      <geometry>
        <mesh
          filename="file:///Users/jae/Library/Mobile Documents/com~apple~CloudDocs/KUDOS/Humanoid/8. URDF 작업/URDF_study/src/QUB_URDF_fin/meshes/R_calf_link.STL" />
      </geometry>
      <material
        name="">
        <color
          rgba="0.752941176470588 0.752941176470588 0.752941176470588 1" />
      </material>
    </visual>
    <collision>
      <origin
        xyz="0 0 0"
        rpy="0 0 0" />
      <geometry>
        <mesh
          filename="file:///Users/jae/Library/Mobile Documents/com~apple~CloudDocs/KUDOS/Humanoid/8. URDF 작업/URDF_study/src/QUB_URDF_fin/meshes/R_calf_link.STL" />
      </geometry>
    </collision>
  </link>
  <joint
    name="R_knee_pitch_joint"
    type="revolute">
    <origin
      xyz="0.00020757 -0.00015 -0.158"
      rpy="0 0 0" />
    <parent
      link="R_thigh_link" />
    <child
      link="R_calf_link" />
    <axis
      xyz="0 -1 0" />
    <limit
      lower="-2.62"
      upper="0.0"
      effort="150"
      velocity="10" />
  </joint>
  <link
    name="R_ankle_link">
    <inertial>
      <origin
        xyz="0.0 0.0 -0.00007"
        rpy="0 0 0" />
      <mass
        value="0.02200" />
      <inertia
        ixx="1.99627E-06"
        ixy="0.0"
        ixz="0.0"
        iyy="4.89237E-06"
        iyz="0.0"
        izz="5.28341E-06" />
    </inertial>
    <visual>
      <origin
        xyz="0 0 0"
        rpy="0 0 0" />
      <geometry>
        <mesh
          filename="file:///Users/jae/Library/Mobile Documents/com~apple~CloudDocs/KUDOS/Humanoid/8. URDF 작업/URDF_study/src/QUB_URDF_fin/meshes/R_ankle_link.STL" />
      </geometry>
      <material
        name="">
        <color
          rgba="0.698039215686274 0.698039215686274 0.698039215686274 1" />
      </material>
    </visual>
    <collision>
      <origin
        xyz="0 0 0"
        rpy="0 0 0" />
      <geometry>
        <mesh
          filename="file:///Users/jae/Library/Mobile Documents/com~apple~CloudDocs/KUDOS/Humanoid/8. URDF 작업/URDF_study/src/QUB_URDF_fin/meshes/R_ankle_link.STL" />
      </geometry>
    </collision>
  </link>
  <joint
    name="R_ankle_pitch_joint"
    type="revolute">
    <origin
      xyz="0 0.00015 -0.2"
      rpy="0 0 0" />
    <parent
      link="R_calf_link" />
    <child
      link="R_ankle_link" />
    <axis
      xyz="0 -1 0" />
    <limit
      lower="-0.78"
      upper="0.78"
      effort="80"
      velocity="10" />
  </joint>
  <link
    name="R_foot_link">
    <inertial>
      <origin
        xyz="0.00315 0.0 -0.02405"
        rpy="0 0 0" />
      <mass
        value="0.25200" />
      <inertia
        ixx="0.00013745"
        ixy="0.0"
        ixz="-0.000044769"
        iyy="0.00091295"
        iyz="0.0"
        izz="0.00097384" />
    </inertial>
    <visual>
      <origin
        xyz="0 0 -0.038"
        rpy="0 0 0" />
      <geometry>
        <mesh
          filename="file:///Users/jae/Library/Mobile Documents/com~apple~CloudDocs/KUDOS/Humanoid/8. URDF 작업/URDF_study/src/QUB_URDF_fin/meshes/R_foot_link.STL" />
      </geometry>
      <material
        name="">
        <color
          rgba="0.752941176470588 0.752941176470588 0.752941176470588 1" />
      </material>
    </visual>
    <collision>
      <origin
        xyz="0 0 -0.038"
        rpy="0 0 0" />
      <geometry>
        <mesh
          filename="file:///Users/jae/Library/Mobile Documents/com~apple~CloudDocs/KUDOS/Humanoid/8. URDF 작업/URDF_study/src/QUB_URDF_fin/meshes/R_foot_link.STL" />
      </geometry>
    </collision>
  </link>
  <joint
    name="R_ankle_roll_joint"
    type="revolute">
    <origin
      xyz="0 0 0"
      rpy="0 0 0" />
    <parent
      link="R_ankle_link" />
    <child
      link="R_foot_link" />
    <axis
      xyz="1 0 0" />
    <limit
      lower="-0.52"
      upper="0.52"
      effort="80"
      velocity="10" />
  </joint>
  <link
    name="L_hip_r_link">
    <inertial>
      <origin
        xyz="0.00347 -0.00277 -0.00048"
        rpy="0 0 0" />
      <mass
        value="1.24854" />
      <inertia
        ixx="0.0018401"
        ixy="0.00000032265"
        ixz="0.0000071076"
        iyy="0.0013999"
        iyz="-0.000010876"
        izz="0.0013711" />
    </inertial>
    <visual>
      <origin
        xyz="0 0 0"
        rpy="0 0 0" />
      <geometry>
        <mesh
          filename="file:///Users/jae/Library/Mobile Documents/com~apple~CloudDocs/KUDOS/Humanoid/8. URDF 작업/URDF_study/src/QUB_URDF_fin/meshes/L_hip_r_link.STL" />
      </geometry>
      <material
        name="">
        <color
          rgba="0.75294 0.75294 0.75294 1" />
      </material>
    </visual>
    <collision>
      <origin
        xyz="0 0 0"
        rpy="0 0 0" />
      <geometry>
        <mesh
          filename="file:///Users/jae/Library/Mobile Documents/com~apple~CloudDocs/KUDOS/Humanoid/8. URDF 작업/URDF_study/src/QUB_URDF_fin/meshes/L_hip_r_link.STL" />
      </geometry>
    </collision>
  </link>
  <joint
    name="L_hip_pitch_joint"
    type="revolute">
    <origin
      xyz="0 0.1165 0"
      rpy="0 0 0" />
    <parent
      link="pelvis_link" />
    <child
      link="L_hip_r_link" />
    <axis
      xyz="0 1 0" />
    <limit
      lower="-1.57"
      upper="1.57"
      effort="150"
      velocity="10" />
  </joint>
  <link
    name="L_hip_y_link">
    <inertial>
      <origin
        xyz="-0.00135 0.00025 -0.09201"
        rpy="0 0 0" />
      <mass
        value="1.32879" />
      <inertia
        ixx="0.0024344"
        ixy="-0.000013039"
        ixz="-0.00013352"
        iyy="0.0027093"
        iyz="0.000022509"
        izz="0.0019780" />
    </inertial>
    <visual>
      <origin
        xyz="0 0 0"
        rpy="0 0 0" />
      <geometry>
        <mesh
          filename="file:///Users/jae/Library/Mobile Documents/com~apple~CloudDocs/KUDOS/Humanoid/8. URDF 작업/URDF_study/src/QUB_URDF_fin/meshes/L_hip_y_link.STL" />
      </geometry>
      <material
        name="">
        <color
          rgba="0.75294 0.75294 0.75294 1" />
      </material>
    </visual>
    <collision>
      <origin
        xyz="0 0 0"
        rpy="0 0 0" />
      <geometry>
        <mesh
          filename="file:///Users/jae/Library/Mobile Documents/com~apple~CloudDocs/KUDOS/Humanoid/8. URDF 작업/URDF_study/src/QUB_URDF_fin/meshes/L_hip_y_link.STL" />
      </geometry>
    </collision>
  </link>
  <joint
    name="L_hip_roll_joint"
    type="revolute">
    <origin
      xyz="0 0 0"
      rpy="0 0 0" />
    <parent
      link="L_hip_r_link" />
    <child
      link="L_hip_y_link" />
    <axis
      xyz="1 0 0" />
    <limit
      lower="-0.78"
      upper="0.78"
      effort="150"
      velocity="10" />
  </joint>
  <link
    name="L_thigh_link">
    <inertial>
      <origin
        xyz="-0.00659 0.01600 -0.00218"
        rpy="0 0 0" />
      <mass
        value="2.18164" />
      <inertia
        ixx="0.0052252"
        ixy="-0.00017617"
        ixz="0.000090039"
        iyy="0.0051854"
        iyz="0.000055426"
        izz="0.0040697" />
    </inertial>
    <visual>
      <origin
        xyz="0 0 0"
        rpy="0 0 0" />
      <geometry>
        <mesh
          filename="file:///Users/jae/Library/Mobile Documents/com~apple~CloudDocs/KUDOS/Humanoid/8. URDF 작업/URDF_study/src/QUB_URDF_fin/meshes/L_thigh_link.STL" />
      </geometry>
      <material
        name="">
        <color
          rgba="0.75294 0.75294 0.75294 1" />
      </material>
    </visual>
    <collision>
      <origin
        xyz="0 0 0"
        rpy="0 0 0" />
      <geometry>
        <mesh
          filename="file:///Users/jae/Library/Mobile Documents/com~apple~CloudDocs/KUDOS/Humanoid/8. URDF 작업/URDF_study/src/QUB_URDF_fin/meshes/L_thigh_link.STL" />
      </geometry>
    </collision>
  </link>
  <joint
    name="L_hip_yaw_joint"
    type="revolute">
    <origin
      xyz="0 0 -0.21175"
      rpy="0 0 0" />
    <parent
      link="L_hip_y_link" />
    <child
      link="L_thigh_link" />
    <axis
      xyz="0 0 1" />
    <limit
      lower="-0.78"
      upper="0.78"
      effort="100"
      velocity="10" />
  </joint>
  <link
    name="L_calf_link">
    <inertial>
      <origin
        xyz="0.01269 -0.00090 -0.10244"
        rpy="0 0 0" />
      <mass
        value="1.97157" />
      <inertia
        ixx="0.011151"
        ixy="-0.000015627"
        ixz="0.0019738"
        iyy="0.011825"
        iyz="-0.00018350"
        izz="0.0038490" />
    </inertial>
    <visual>
      <origin
        xyz="0 0 0"
        rpy="0 0 0" />
      <geometry>
        <mesh
          filename="file:///Users/jae/Library/Mobile Documents/com~apple~CloudDocs/KUDOS/Humanoid/8. URDF 작업/URDF_study/src/QUB_URDF_fin/meshes/L_calf_link.STL" />
      </geometry>
      <material
        name="">
        <color
          rgba="0.752941176470588 0.752941176470588 0.752941176470588 1" />
      </material>
    </visual>
    <collision>
      <origin
        xyz="0 0 0"
        rpy="0 0 0" />
      <geometry>
        <mesh
          filename="file:///Users/jae/Library/Mobile Documents/com~apple~CloudDocs/KUDOS/Humanoid/8. URDF 작업/URDF_study/src/QUB_URDF_fin/meshes/L_calf_link.STL" />
      </geometry>
    </collision>
  </link>
  <joint
    name="L_knee_pitch_joint"
    type="revolute">
    <origin
      xyz="0.00020757 -0.00015 -0.158"
      rpy="0 0 0" />
    <parent
      link="L_thigh_link" />
    <child
      link="L_calf_link" />
    <axis
      xyz="0 -1 0" />
    <limit
      lower="-2.62"
      upper="0.0"
      effort="150"
      velocity="10" />
  </joint>
  <link
    name="L_ankle_link">
    <inertial>
      <origin
        xyz="0.0 0.0 -0.00007"
        rpy="0 0 0" />
      <mass
        value="0.02200" />
      <inertia
        ixx="1.99627E-06"
        ixy="0.0"
        ixz="0.0"
        iyy="4.89237E-06"
        iyz="0.0"
        izz="5.28341E-06" />
    </inertial>
    <visual>
      <origin
        xyz="0 0 0"
        rpy="0 0 0" />
      <geometry>
        <mesh
          filename="file:///Users/jae/Library/Mobile Documents/com~apple~CloudDocs/KUDOS/Humanoid/8. URDF 작업/URDF_study/src/QUB_URDF_fin/meshes/L_ankle_link.STL" />
      </geometry>
      <material
        name="">
        <color
          rgba="0.698039215686274 0.698039215686274 0.698039215686274 1" />
      </material>
    </visual>
    <collision>
      <origin
        xyz="0 0 0"
        rpy="0 0 0" />
      <geometry>
        <mesh
          filename="file:///Users/jae/Library/Mobile Documents/com~apple~CloudDocs/KUDOS/Humanoid/8. URDF 작업/URDF_study/src/QUB_URDF_fin/meshes/L_ankle_link.STL" />
      </geometry>
    </collision>
  </link>
  <joint
    name="L_ankle_pitch_joint"
    type="revolute">
    <origin
      xyz="0 0.00015 -0.20139"
      rpy="0 0 0" />
    <parent
      link="L_calf_link" />
    <child
      link="L_ankle_link" />
    <axis
      xyz="0 1 0" />
    <limit
      lower="-0.78"
      upper="0.78"
      effort="80"
      velocity="10" />
  </joint>
  <link
    name="L_foot_link">
    <inertial>
      <origin
        xyz="0.00315 0.0 -0.02405"
        rpy="0 0 0" />
      <mass
        value="0.25200" />
      <inertia
        ixx="0.00013745"
        ixy="0.0"
        ixz="-0.000044769"
        iyy="0.00091295"
        iyz="0.0"
        izz="0.00097384" />
    </inertial>
    <visual>
      <origin
        xyz="0 0 -0.038"
        rpy="0 0 0" />
      <geometry>
        <mesh
          filename="file:///Users/jae/Library/Mobile Documents/com~apple~CloudDocs/KUDOS/Humanoid/8. URDF 작업/URDF_study/src/QUB_URDF_fin/meshes/L_foot_link.STL" />
      </geometry>
      <material
        name="">
        <color
          rgba="0.752941176470588 0.752941176470588 0.752941176470588 1" />
      </material>
    </visual>
    <collision>
      <origin
        xyz="0 0 -0.038"
        rpy="0 0 0" />
      <geometry>
        <mesh
          filename="file:///Users/jae/Library/Mobile Documents/com~apple~CloudDocs/KUDOS/Humanoid/8. URDF 작업/URDF_study/src/QUB_URDF_fin/meshes/L_foot_link.STL" />
      </geometry>
    </collision>
  </link>
  <joint
    name="L_ankle_roll_joint"
    type="revolute">
    <origin
      xyz="0 0 0"
      rpy="0 0 0" />
    <parent
      link="L_ankle_link" />
    <child
      link="L_foot_link" />
    <axis
      xyz="1 0 0" />
    <limit
      lower="-0.52"
      upper="0.52"
      effort="80"
      velocity="10" />
  </joint>
</robot>