<?xml version="1.0" encoding="utf-8"?>
<!-- This URDF was automatically created by SolidWorks to URDF Exporter! Originally created by Stephen Brawner (brawner@gmail.com) 
     Commit Version: 1.6.0-4-g7f85cfe  Build Version: 1.6.7995.38578
     For more information, please see http://wiki.ros.org/sw_urdf_exporter -->
<robot
  name="QUB v1.2 urdf">
  <link
    name="base_link">
    <inertial>
      <origin
        xyz="0.0001 -0.00145 -0.00018"
        rpy="0 0 0" />
      <mass
        value="4.21449" />
      <inertia
        ixx="0.048051"
        ixy="0.000022089"
        ixz="-0.000049922"
        iyy="0.041201"
        iyz="0.0014077"
        izz="0.021693" />
    </inertial>
    <visual>
      <origin
        xyz="0 0 0"
        rpy="0 0 0" />
      <geometry>
        <mesh
          filename="file:///Users/jae/Library/Mobile Documents/com~apple~CloudDocs/KUDOS/Humanoid/8. URDF 작업/URDF_study/src/QUB_URDF_fin/meshes/base_link.STL" />
      </geometry>
      <material
        name="">
        <color
          rgba="0.75294 0.75294 0.75294 1" />
      </material>
    </visual>
    <collision>
      <origin
        xyz="0 0 0"
        rpy="0 0 0" />
      <geometry>
        <mesh
          filename="file:///Users/jae/Library/Mobile Documents/com~apple~CloudDocs/KUDOS/Humanoid/8. URDF 작업/URDF_study/src/QUB_URDF_fin/meshes/base_link.STL" />
      </geometry>
    </collision>
  </link>
  <link
    name="pelvis_link">
    <inertial>
      <origin
        xyz="-0.00036 0.00024 0.03233"
        rpy="0 0 0" />
      <mass
        value="3.69660" />
      <inertia
        ixx="0.012187"
        ixy="-0.000011794"
        ixz="-0.000096093"
        iyy="0.011785"
        iyz="0.0000034329"
        izz="0.0075662" />
    </inertial>
    <visual>
      <origin
        xyz="0 0 0"
        rpy="0 0 0" />
      <geometry>
        <mesh
          filename="file:///Users/jae/Library/Mobile Documents/com~apple~CloudDocs/KUDOS/Humanoid/8. URDF 작업/URDF_study/src/QUB_URDF_fin/meshes/pelvis_link.STL" />
      </geometry>
      <material
        name="">
        <color
          rgba="0.752941176470588 0.752941176470588 0.752941176470588 1" />
      </material>
    </visual>
    <collision>
      <origin
        xyz="0 0 0"
        rpy="0 0 0" />
      <geometry>
        <mesh
          filename="file:///Users/jae/Library/Mobile Documents/com~apple~CloudDocs/KUDOS/Humanoid/8. URDF 작업/URDF_study/src/QUB_URDF_fin/meshes/pelvis_link.STL" />
      </geometry>
    </collision>
  </link>
  <joint
    name="torso_yaw_joint"
    type="revolute">
    <origin
      xyz="0 0 -0.24162"
      rpy="0 0 0" />
    <parent
      link="base_link" />
    <child
      link="pelvis_link" />
    <axis
      xyz="0 0 1" />
    <limit
      lower="-1.57"
      upper="1.57"
      effort="100"
      velocity="10" />
  </joint>
  <link
    name="R_hip_r_link">
    <inertial>
      <origin
        xyz="0.00347 0.00277 -0.00048"
        rpy="0 0 0" />
      <mass
        value="1.24854" />
      <inertia
        ixx="0.0018401"
        ixy="-0.00000032265"
        ixz="0.0000071076"
        iyy="0.0013999"
        iyz="0.000010876"
        izz="0.0013711" />
    </inertial>
    <visual>
      <origin
        xyz="0 0 0"
        rpy="0 0 0" />
      <geometry>
        <mesh
          filename="file:///Users/jae/Library/Mobile Documents/com~apple~CloudDocs/KUDOS/Humanoid/8. URDF 작업/URDF_study/src/QUB_URDF_fin/meshes/R_hip_r_link.STL" />
      </geometry>
      <material
        name="">
        <color
          rgba="0.75294 0.75294 0.75294 1" />
      </material>
    </visual>
    <collision>
      <origin
        xyz="0 0 0"
        rpy="0 0 0" />
      <geometry>
        <mesh
          filename="file:///Users/jae/Library/Mobile Documents/com~apple~CloudDocs/KUDOS/Humanoid/8. URDF 작업/URDF_study/src/QUB_URDF_fin/meshes/R_hip_r_link.STL" />
      </geometry>
    </collision>
  </link>
  <joint
    name="R_hip_pitch_joint"
    type="revolute">
    <origin
      xyz="0 -0.1159 0"
      rpy="0 0 0" />
    <parent
      link="pelvis_link" />
    <child
      link="R_hip_r_link" />
    <axis
      xyz="0 1 0" />
    <limit
      lower="-1.57"
      upper="1.57"
      effort="150"
      velocity="10" />
  </joint>
  <link
    name="R_hip_y_link">
    <inertial>
      <origin
        xyz="-0.0019326 -0.00037297 -0.084368"
        rpy="0 0 0" />
      <mass
        value="0.91776" />
      <inertia
        ixx="0.0012719"
        ixy="-1.3E-05"
        ixz="5.1455E-05"
        iyy="0.0015267"
        iyz="1.7107E-05"
        izz="0.0015116" />
    </inertial>
    <visual>
      <origin
        xyz="0 0 0"
        rpy="0 0 0" />
      <geometry>
        <mesh
          filename="file:///Users/jae/Library/Mobile Documents/com~apple~CloudDocs/KUDOS/Humanoid/8. URDF 작업/URDF_study/src/QUB_URDF_fin/meshes/R_hip_y_link.STL" />
      </geometry>
      <material
        name="">
        <color
          rgba="0.75294 0.75294 0.75294 1" />
      </material>
    </visual>
    <collision>
      <origin
        xyz="0 0 0"
        rpy="0 0 0" />
      <geometry>
        <mesh
          filename="file:///Users/jae/Library/Mobile Documents/com~apple~CloudDocs/KUDOS/Humanoid/8. URDF 작업/URDF_study/src/QUB_URDF_fin/meshes/R_hip_y_link.STL" />
      </geometry>
    </collision>
  </link>
  <joint
    name="R_hip_roll_joint"
    type="revolute">
    <origin
      xyz="0 0 0"
      rpy="0 0 0" />
    <parent
      link="R_hip_r_link" />
    <child
      link="R_hip_y_link" />
    <axis
      xyz="1 0 0" />
    <limit
      lower="-0.78"
      upper="0.78"
      effort="150"
      velocity="10" />
  </joint>
  <link
    name="R_thigh_link">
    <inertial>
      <origin
        xyz="-0.0043524 -0.0041632 -0.0039421"
        rpy="0 0 0" />
      <mass
        value="1.3747" />
      <inertia
        ixx="0.0037051"
        ixy="3.4405E-05"
        ixz="-0.00016955"
        iyy="0.0039229"
        iyz="-9.6905E-05"
        izz="0.0023114" />
    </inertial>
    <visual>
      <origin
        xyz="0 0 0"
        rpy="0 0 0" />
      <geometry>
        <mesh
          filename="file:///Users/jae/Library/Mobile Documents/com~apple~CloudDocs/KUDOS/Humanoid/8. URDF 작업/URDF_study/src/QUB_URDF_fin/meshes/R_thigh_link.STL" />
      </geometry>
      <material
        name="">
        <color
          rgba="0.75294 0.75294 0.75294 1" />
      </material>
    </visual>
    <collision>
      <origin
        xyz="0 0 0"
        rpy="0 0 0" />
      <geometry>
        <mesh
          filename="file:///Users/jae/Library/Mobile Documents/com~apple~CloudDocs/KUDOS/Humanoid/8. URDF 작업/URDF_study/src/QUB_URDF_fin/meshes/R_thigh_link.STL" />
      </geometry>
    </collision>
  </link>
  <joint
    name="R_hip_yaw_joint"
    type="revolute">
    <origin
      xyz="0 0 -0.21175"
      rpy="0 0 0" />
    <parent
      link="R_hip_y_link" />
    <child
      link="R_thigh_link" />
    <axis
      xyz="0 0 1" />
    <limit
      lower="-0.78"
      upper="0.78"
      effort="100"
      velocity="10" />
  </joint>
  <link
    name="R_calf_link">
    <inertial>
      <origin
        xyz="-0.00421444288490647 0.00175538374686454 -0.0169093460368692"
        rpy="0 0 0" />
      <mass
        value="1.17074722834553" />
      <inertia
        ixx="0.00171475366408221"
        ixy="1.21634495115775E-05"
        ixz="1.29104743847128E-05"
        iyy="0.00205284117205138"
        iyz="-3.91070962256474E-05"
        izz="0.00082226361600516" />
    </inertial>
    <visual>
      <origin
        xyz="0 0 0"
        rpy="0 0 0" />
      <geometry>
        <mesh
          filename="file:///Users/jae/Library/Mobile Documents/com~apple~CloudDocs/KUDOS/Humanoid/8. URDF 작업/URDF_study/src/QUB_URDF_fin/meshes/R_calf_link.STL" />
      </geometry>
      <material
        name="">
        <color
          rgba="0.752941176470588 0.752941176470588 0.752941176470588 1" />
      </material>
    </visual>
    <collision>
      <origin
        xyz="0 0 0"
        rpy="0 0 0" />
      <geometry>
        <mesh
          filename="file:///Users/jae/Library/Mobile Documents/com~apple~CloudDocs/KUDOS/Humanoid/8. URDF 작업/URDF_study/src/QUB_URDF_fin/meshes/R_calf_link.STL" />
      </geometry>
    </collision>
  </link>
  <joint
    name="R_knee_pitch_joint"
    type="revolute">
    <origin
      xyz="0.00020757 -0.00015 -0.158"
      rpy="0 0 0" />
    <parent
      link="R_thigh_link" />
    <child
      link="R_calf_link" />
    <axis
      xyz="0 -1 0" />
    <limit
      lower="-2.62"
      upper="0.0"
      effort="150"
      velocity="10" />
  </joint>
  <link
    name="R_ankle_link">
    <inertial>
      <origin
        xyz="-2.66453525910038E-15 2.77555756156289E-17 -7.07699960694752E-05"
        rpy="0 0 0" />
      <mass
        value="0.0236524344915325" />
      <inertia
        ixx="2.14621271212166E-06"
        ixy="1.00084600834964E-22"
        ixz="1.30995379297544E-16"
        iyy="5.2598431858044E-06"
        iyz="-1.76283693796845E-19"
        izz="5.68025550439875E-06" />
    </inertial>
    <visual>
      <origin
        xyz="0 0 0"
        rpy="0 0 0" />
      <geometry>
        <mesh
          filename="file:///Users/jae/Library/Mobile Documents/com~apple~CloudDocs/KUDOS/Humanoid/8. URDF 작업/URDF_study/src/QUB_URDF_fin/meshes/R_ankle_link.STL" />
      </geometry>
      <material
        name="">
        <color
          rgba="0.698039215686274 0.698039215686274 0.698039215686274 1" />
      </material>
    </visual>
    <collision>
      <origin
        xyz="0 0 0"
        rpy="0 0 0" />
      <geometry>
        <mesh
          filename="file:///Users/jae/Library/Mobile Documents/com~apple~CloudDocs/KUDOS/Humanoid/8. URDF 작업/URDF_study/src/QUB_URDF_fin/meshes/R_ankle_link.STL" />
      </geometry>
    </collision>
  </link>
  <joint
    name="R_ankle_pitch_joint"
    type="revolute">
    <origin
      xyz="0 0.00015 -0.2"
      rpy="0 0 0" />
    <parent
      link="R_calf_link" />
    <child
      link="R_ankle_link" />
    <axis
      xyz="0 -1 0" />
    <limit
      lower="-0.78"
      upper="0.78"
      effort="80"
      velocity="10" />
  </joint>
  <link
    name="R_foot_link">
    <inertial>
      <origin
        xyz="0.00281002392594654 -8.30484570002454E-10 -0.0247444314545938"
        rpy="0 0 0" />
      <mass
        value="0.359946548475121" />
      <inertia
        ixx="0.000172849957125141"
        ixy="1.38491242777396E-10"
        ixz="4.71243721626092E-06"
        iyy="0.000707347286151241"
        iyz="-2.38539533791978E-11"
        izz="0.000833012227059178" />
    </inertial>
    <visual>
      <origin
        xyz="0 0 -0.038"
        rpy="0 0 0" />
      <geometry>
        <mesh
          filename="file:///Users/jae/Library/Mobile Documents/com~apple~CloudDocs/KUDOS/Humanoid/8. URDF 작업/URDF_study/src/QUB_URDF_fin/meshes/R_foot_link.STL" />
      </geometry>
      <material
        name="">
        <color
          rgba="0.752941176470588 0.752941176470588 0.752941176470588 1" />
      </material>
    </visual>
    <collision>
      <origin
        xyz="0 0 -0.038"
        rpy="0 0 0" />
      <geometry>
        <mesh
          filename="file:///Users/jae/Library/Mobile Documents/com~apple~CloudDocs/KUDOS/Humanoid/8. URDF 작업/URDF_study/src/QUB_URDF_fin/meshes/R_foot_link.STL" />
      </geometry>
    </collision>
  </link>
  <joint
    name="R_ankle_roll_joint"
    type="revolute">
    <origin
      xyz="0 0 0"
      rpy="0 0 0" />
    <parent
      link="R_ankle_link" />
    <child
      link="R_foot_link" />
    <axis
      xyz="1 0 0" />
    <limit
      lower="-0.52"
      upper="0.52"
      effort="80"
      velocity="10" />
  </joint>
  <link
    name="L_hip_r_link">
    <inertial>
      <origin
        xyz="0.00347 -0.00277 -0.00048"
        rpy="0 0 0" />
      <mass
        value="1.24854" />
      <inertia
        ixx="0.0018401"
        ixy="0.00000032265"
        ixz="0.0000071076"
        iyy="0.0013999"
        iyz="-0.000010876"
        izz="0.0013711" />
    </inertial>
    <visual>
      <origin
        xyz="0 0 0"
        rpy="0 0 0" />
      <geometry>
        <mesh
          filename="file:///Users/jae/Library/Mobile Documents/com~apple~CloudDocs/KUDOS/Humanoid/8. URDF 작업/URDF_study/src/QUB_URDF_fin/meshes/L_hip_r_link.STL" />
      </geometry>
      <material
        name="">
        <color
          rgba="0.75294 0.75294 0.75294 1" />
      </material>
    </visual>
    <collision>
      <origin
        xyz="0 0 0"
        rpy="0 0 0" />
      <geometry>
        <mesh
          filename="file:///Users/jae/Library/Mobile Documents/com~apple~CloudDocs/KUDOS/Humanoid/8. URDF 작업/URDF_study/src/QUB_URDF_fin/meshes/L_hip_r_link.STL" />
      </geometry>
    </collision>
  </link>
  <joint
    name="L_hip_pitch_joint"
    type="revolute">
    <origin
      xyz="0 0.1165 0"
      rpy="0 0 0" />
    <parent
      link="pelvis_link" />
    <child
      link="L_hip_r_link" />
    <axis
      xyz="0 1 0" />
    <limit
      lower="-1.57"
      upper="1.57"
      effort="150"
      velocity="10" />
  </joint>
  <link
    name="L_hip_y_link">
    <inertial>
      <origin
        xyz="-0.0019325 0.000177 -0.085754"
        rpy="0 0 0" />
      <mass
        value="0.91776" />
      <inertia
        ixx="0.0012719"
        ixy="6.5681E-06"
        ixz="5.1456E-05"
        iyy="0.0015267"
        iyz="-1.623E-05"
        izz="0.0015116" />
    </inertial>
    <visual>
      <origin
        xyz="0 0 0"
        rpy="0 0 0" />
      <geometry>
        <mesh
          filename="file:///Users/jae/Library/Mobile Documents/com~apple~CloudDocs/KUDOS/Humanoid/8. URDF 작업/URDF_study/src/QUB_URDF_fin/meshes/L_hip_y_link.STL" />
      </geometry>
      <material
        name="">
        <color
          rgba="0.75294 0.75294 0.75294 1" />
      </material>
    </visual>
    <collision>
      <origin
        xyz="0 0 0"
        rpy="0 0 0" />
      <geometry>
        <mesh
          filename="file:///Users/jae/Library/Mobile Documents/com~apple~CloudDocs/KUDOS/Humanoid/8. URDF 작업/URDF_study/src/QUB_URDF_fin/meshes/L_hip_y_link.STL" />
      </geometry>
    </collision>
  </link>
  <joint
    name="L_hip_roll_joint"
    type="revolute">
    <origin
      xyz="0 0 0"
      rpy="0 0 0" />
    <parent
      link="L_hip_r_link" />
    <child
      link="L_hip_y_link" />
    <axis
      xyz="1 0 0" />
    <limit
      lower="-0.78"
      upper="0.78"
      effort="150"
      velocity="10" />
  </joint>
  <link
    name="L_thigh_link">
    <inertial>
      <origin
        xyz="-0.0043129 0.0041632 -0.0058352"
        rpy="0 0 0" />
      <mass
        value="1.3747" />
      <inertia
        ixx="0.0036969"
        ixy="-3.4371E-05"
        ixz="-0.00017351"
        iyy="0.003923"
        iyz="9.6608E-05"
        izz="0.0023197" />
    </inertial>
    <visual>
      <origin
        xyz="0 0 0"
        rpy="0 0 0" />
      <geometry>
        <mesh
          filename="file:///Users/jae/Library/Mobile Documents/com~apple~CloudDocs/KUDOS/Humanoid/8. URDF 작업/URDF_study/src/QUB_URDF_fin/meshes/L_thigh_link.STL" />
      </geometry>
      <material
        name="">
        <color
          rgba="0.75294 0.75294 0.75294 1" />
      </material>
    </visual>
    <collision>
      <origin
        xyz="0 0 0"
        rpy="0 0 0" />
      <geometry>
        <mesh
          filename="file:///Users/jae/Library/Mobile Documents/com~apple~CloudDocs/KUDOS/Humanoid/8. URDF 작업/URDF_study/src/QUB_URDF_fin/meshes/L_thigh_link.STL" />
      </geometry>
    </collision>
  </link>
  <joint
    name="L_hip_yaw_joint"
    type="revolute">
    <origin
      xyz="0 0 -0.21175"
      rpy="0 0 0" />
    <parent
      link="L_hip_y_link" />
    <child
      link="L_thigh_link" />
    <axis
      xyz="0 0 1" />
    <limit
      lower="-0.78"
      upper="0.78"
      effort="100"
      velocity="10" />
  </joint>
  <link
    name="L_calf_link">
    <inertial>
      <origin
        xyz="-0.00420634175048007 -0.00158074866388551 -0.018640491907174"
        rpy="0 0 0" />
      <mass
        value="1.17074763980287" />
      <inertia
        ixx="0.00171485592722464"
        ixy="-1.21493848391669E-05"
        ixz="1.07228309206104E-05"
        iyy="0.00205284077692005"
        iyz="3.91222447518983E-05"
        izz="0.000822161500709759" />
    </inertial>
    <visual>
      <origin
        xyz="0 0 0"
        rpy="0 0 0" />
      <geometry>
        <mesh
          filename="file:///Users/jae/Library/Mobile Documents/com~apple~CloudDocs/KUDOS/Humanoid/8. URDF 작업/URDF_study/src/QUB_URDF_fin/meshes/L_calf_link.STL" />
      </geometry>
      <material
        name="">
        <color
          rgba="0.752941176470588 0.752941176470588 0.752941176470588 1" />
      </material>
    </visual>
    <collision>
      <origin
        xyz="0 0 0"
        rpy="0 0 0" />
      <geometry>
        <mesh
          filename="file:///Users/jae/Library/Mobile Documents/com~apple~CloudDocs/KUDOS/Humanoid/8. URDF 작업/URDF_study/src/QUB_URDF_fin/meshes/L_calf_link.STL" />
      </geometry>
    </collision>
  </link>
  <joint
    name="L_knee_pitch_joint"
    type="revolute">
    <origin
      xyz="0.00020757 -0.00015 -0.158"
      rpy="0 0 0" />
    <parent
      link="L_thigh_link" />
    <child
      link="L_calf_link" />
    <axis
      xyz="0 -1 0" />
    <limit
      lower="-2.62"
      upper="0.0"
      effort="150"
      velocity="10" />
  </joint>
  <link
    name="L_ankle_link">
    <inertial>
      <origin
        xyz="-2.66453525910038E-15 4.16333634234434E-17 -7.07699960693642E-05"
        rpy="0 0 0" />
      <mass
        value="0.0236524344915326" />
      <inertia
        ixx="2.14621271212167E-06"
        ixy="-6.54874238162791E-22"
        ixz="1.30994850864923E-16"
        iyy="5.25984318580441E-06"
        iyz="-1.77152176280747E-19"
        izz="5.68025550439876E-06" />
    </inertial>
    <visual>
      <origin
        xyz="0 0 0"
        rpy="0 0 0" />
      <geometry>
        <mesh
          filename="file:///Users/jae/Library/Mobile Documents/com~apple~CloudDocs/KUDOS/Humanoid/8. URDF 작업/URDF_study/src/QUB_URDF_fin/meshes/L_ankle_link.STL" />
      </geometry>
      <material
        name="">
        <color
          rgba="0.698039215686274 0.698039215686274 0.698039215686274 1" />
      </material>
    </visual>
    <collision>
      <origin
        xyz="0 0 0"
        rpy="0 0 0" />
      <geometry>
        <mesh
          filename="file:///Users/jae/Library/Mobile Documents/com~apple~CloudDocs/KUDOS/Humanoid/8. URDF 작업/URDF_study/src/QUB_URDF_fin/meshes/L_ankle_link.STL" />
      </geometry>
    </collision>
  </link>
  <joint
    name="L_ankle_pitch_joint"
    type="revolute">
    <origin
      xyz="0 0.00015 -0.20139"
      rpy="0 0 0" />
    <parent
      link="L_calf_link" />
    <child
      link="L_ankle_link" />
    <axis
      xyz="0 1 0" />
    <limit
      lower="-0.78"
      upper="0.78"
      effort="80"
      velocity="10" />
  </joint>
  <link
    name="L_foot_link">
    <inertial>
      <origin
        xyz="0.00281002393642815 -8.31067381579231E-10 -0.0247444314516908"
        rpy="0 0 0" />
      <mass
        value="0.359946548540282" />
      <inertia
        ixx="0.000172849957126261"
        ixy="1.38488466574984E-10"
        ixz="4.7124372100159E-06"
        iyy="0.000707347286142948"
        iyz="-2.38507070794971E-11"
        izz="0.000833012227042146" />
    </inertial>
    <visual>
      <origin
        xyz="0 0 -0.038"
        rpy="0 0 0" />
      <geometry>
        <mesh
          filename="file:///Users/jae/Library/Mobile Documents/com~apple~CloudDocs/KUDOS/Humanoid/8. URDF 작업/URDF_study/src/QUB_URDF_fin/meshes/L_foot_link.STL" />
      </geometry>
      <material
        name="">
        <color
          rgba="0.752941176470588 0.752941176470588 0.752941176470588 1" />
      </material>
    </visual>
    <collision>
      <origin
        xyz="0 0 -0.038"
        rpy="0 0 0" />
      <geometry>
        <mesh
          filename="file:///Users/jae/Library/Mobile Documents/com~apple~CloudDocs/KUDOS/Humanoid/8. URDF 작업/URDF_study/src/QUB_URDF_fin/meshes/L_foot_link.STL" />
      </geometry>
    </collision>
  </link>
  <joint
    name="L_ankle_roll_joint"
    type="revolute">
    <origin
      xyz="0 0 0"
      rpy="0 0 0" />
    <parent
      link="L_ankle_link" />
    <child
      link="L_foot_link" />
    <axis
      xyz="1 0 0" />
    <limit
      lower="-0.52"
      upper="0.52"
      effort="80"
      velocity="10" />
  </joint>
</robot>